2025-10-25 22:50:44 - telegram.ext.Updater - ERROR - Exception happened while polling for updates.
Traceback (most recent call last):
  File "/root/SWB/venv/lib/python3.13/site-packages/telegram/ext/_utils/networkloop.py", line 134, in network_retry_loop
    await do_action()
  File "/root/SWB/venv/lib/python3.13/site-packages/telegram/ext/_utils/networkloop.py", line 127, in do_action
    action_cb_task.result()
    ~~~~~~~~~~~~~~~~~~~~~^^
  File "/root/SWB/venv/lib/python3.13/site-packages/telegram/ext/_updater.py", line 340, in polling_action_cb
    updates = await self.bot.get_updates(
              ^^^^^^^^^^^^^^^^^^^^^^^^^^^
    ...<3 lines>...
    )
    ^
  File "/root/SWB/venv/lib/python3.13/site-packages/telegram/ext/_extbot.py", line 676, in get_updates
    updates = await super().get_updates(
              ^^^^^^^^^^^^^^^^^^^^^^^^^^
    ...<9 lines>...
    )
    ^
  File "/root/SWB/venv/lib/python3.13/site-packages/telegram/_bot.py", line 4780, in get_updates
    await self._post(
    ^^^^^^^^^^^^^^^^^
    ...<7 lines>...
    ),
    ^
  File "/root/SWB/venv/lib/python3.13/site-packages/telegram/_bot.py", line 703, in _post
    return await self._do_post(
           ^^^^^^^^^^^^^^^^^^^^
    ...<6 lines>...
    )
    ^
  File "/root/SWB/venv/lib/python3.13/site-packages/telegram/ext/_extbot.py", line 372, in _do_post
    return await super()._do_post(
           ^^^^^^^^^^^^^^^^^^^^^^^
    ...<6 lines>...
    )
    ^
  File "/root/SWB/venv/lib/python3.13/site-packages/telegram/_bot.py", line 732, in _do_post
    result = await request.post(
             ^^^^^^^^^^^^^^^^^^^
    ...<6 lines>...
    )
    ^
  File "/root/SWB/venv/lib/python3.13/site-packages/telegram/request/_baserequest.py", line 198, in post
    result = await self._request_wrapper(
             ^^^^^^^^^^^^^^^^^^^^^^^^^^^^
    ...<7 lines>...
    )
    ^
  File "/root/SWB/venv/lib/python3.13/site-packages/telegram/request/_baserequest.py", line 375, in _request_wrapper
    raise exception
telegram.error.Conflict: Conflict: terminated by other getUpdates request; make sure that only one bot instance is running
2025-10-25 22:50:44 - telegram.ext.Updater - ERROR - Exception happened while polling for updates.
Traceback (most recent call last):
  File "/root/SWB/venv/lib/python3.13/site-packages/telegram/ext/_utils/networkloop.py", line 134, in network_retry_loop
    await do_action()
  File "/root/SWB/venv/lib/python3.13/site-packages/telegram/ext/_utils/networkloop.py", line 127, in do_action
    action_cb_task.result()
    ~~~~~~~~~~~~~~~~~~~~~^^
  File "/root/SWB/venv/lib/python3.13/site-packages/telegram/ext/_updater.py", line 340, in polling_action_cb
    updates = await self.bot.get_updates(
              ^^^^^^^^^^^^^^^^^^^^^^^^^^^
    ...<3 lines>...
    )
    ^
  File "/root/SWB/venv/lib/python3.13/site-packages/telegram/ext/_extbot.py", line 676, in get_updates
    updates = await super().get_updates(
              ^^^^^^^^^^^^^^^^^^^^^^^^^^
    ...<9 lines>...
    )
    ^
  File "/root/SWB/venv/lib/python3.13/site-packages/telegram/_bot.py", line 4780, in get_updates
    await self._post(
    ^^^^^^^^^^^^^^^^^
    ...<7 lines>...
    ),
    ^
  File "/root/SWB/venv/lib/python3.13/site-packages/telegram/_bot.py", line 703, in _post
    return await self._do_post(
           ^^^^^^^^^^^^^^^^^^^^
    ...<6 lines>...
    )
    ^
  File "/root/SWB/venv/lib/python3.13/site-packages/telegram/ext/_extbot.py", line 372, in _do_post
    return await super()._do_post(
           ^^^^^^^^^^^^^^^^^^^^^^^
    ...<6 lines>...
    )
    ^
  File "/root/SWB/venv/lib/python3.13/site-packages/telegram/_bot.py", line 732, in _do_post
    result = await request.post(
             ^^^^^^^^^^^^^^^^^^^
    ...<6 lines>...
    )
    ^
  File "/root/SWB/venv/lib/python3.13/site-packages/telegram/request/_baserequest.py", line 198, in post
    result = await self._request_wrapper(
             ^^^^^^^^^^^^^^^^^^^^^^^^^^^^
    ...<7 lines>...
    )
    ^
  File "/root/SWB/venv/lib/python3.13/site-packages/telegram/request/_baserequest.py", line 375, in _request_wrapper
    raise exception
telegram.error.Conflict: Conflict: terminated by other getUpdates request; make sure that only one bot instance is running
2025-10-25 22:50:50 - telegram.ext.Updater - ERROR - Exception happened while polling for updates.
Traceback (most recent call last):
  File "/root/SWB/venv/lib/python3.13/site-packages/telegram/ext/_utils/networkloop.py", line 134, in network_retry_loop
    await do_action()
  File "/root/SWB/venv/lib/python3.13/site-packages/telegram/ext/_utils/networkloop.py", line 127, in do_action
    action_cb_task.result()
    ~~~~~~~~~~~~~~~~~~~~~^^
  File "/root/SWB/venv/lib/python3.13/site-packages/telegram/ext/_updater.py", line 340, in polling_action_cb
    updates = await self.bot.get_updates(
              ^^^^^^^^^^^^^^^^^^^^^^^^^^^
    ...<3 lines>...
    )
    ^
  File "/root/SWB/venv/lib/python3.13/site-packages/telegram/ext/_extbot.py", line 676, in get_updates
    updates = await super().get_updates(
              ^^^^^^^^^^^^^^^^^^^^^^^^^^
    ...<9 lines>...
    )
    ^
  File "/root/SWB/venv/lib/python3.13/site-packages/telegram/_bot.py", line 4780, in get_updates
    await self._post(
    ^^^^^^^^^^^^^^^^^
    ...<7 lines>...
    ),
    ^
  File "/root/SWB/venv/lib/python3.13/site-packages/telegram/_bot.py", line 703, in _post
    return await self._do_post(
           ^^^^^^^^^^^^^^^^^^^^
    ...<6 lines>...
    )
    ^
  File "/root/SWB/venv/lib/python3.13/site-packages/telegram/ext/_extbot.py", line 372, in _do_post
    return await super()._do_post(
           ^^^^^^^^^^^^^^^^^^^^^^^
    ...<6 lines>...
    )
    ^
  File "/root/SWB/venv/lib/python3.13/site-packages/telegram/_bot.py", line 732, in _do_post
    result = await request.post(
             ^^^^^^^^^^^^^^^^^^^
    ...<6 lines>...
    )
    ^
  File "/root/SWB/venv/lib/python3.13/site-packages/telegram/request/_baserequest.py", line 198, in post
    result = await self._request_wrapper(
             ^^^^^^^^^^^^^^^^^^^^^^^^^^^^
    ...<7 lines>...
    )
    ^
  File "/root/SWB/venv/lib/python3.13/site-packages/telegram/request/_baserequest.py", line 375, in _request_wrapper
    raise exception
telegram.error.Conflict: Conflict: terminated by other getUpdates request; make sure that only one bot instance is running
2025-10-25 22:50:50 - telegram.ext.Updater - ERROR - Exception happened while polling for updates.
Traceback (most recent call last):
  File "/root/SWB/venv/lib/python3.13/site-packages/telegram/ext/_utils/networkloop.py", line 134, in network_retry_loop
    await do_action()
  File "/root/SWB/venv/lib/python3.13/site-packages/telegram/ext/_utils/networkloop.py", line 127, in do_action
    action_cb_task.result()
    ~~~~~~~~~~~~~~~~~~~~~^^
  File "/root/SWB/venv/lib/python3.13/site-packages/telegram/ext/_updater.py", line 340, in polling_action_cb
    updates = await self.bot.get_updates(
              ^^^^^^^^^^^^^^^^^^^^^^^^^^^
    ...<3 lines>...
    )
    ^
  File "/root/SWB/venv/lib/python3.13/site-packages/telegram/ext/_extbot.py", line 676, in get_updates
    updates = await super().get_updates(
              ^^^^^^^^^^^^^^^^^^^^^^^^^^
    ...<9 lines>...
    )
    ^
  File "/root/SWB/venv/lib/python3.13/site-packages/telegram/_bot.py", line 4780, in get_updates
    await self._post(
    ^^^^^^^^^^^^^^^^^
    ...<7 lines>...
    ),
    ^
  File "/root/SWB/venv/lib/python3.13/site-packages/telegram/_bot.py", line 703, in _post
    return await self._do_post(
           ^^^^^^^^^^^^^^^^^^^^
    ...<6 lines>...
    )
    ^
  File "/root/SWB/venv/lib/python3.13/site-packages/telegram/ext/_extbot.py", line 372, in _do_post
    return await super()._do_post(
           ^^^^^^^^^^^^^^^^^^^^^^^
    ...<6 lines>...
    )
    ^
  File "/root/SWB/venv/lib/python3.13/site-packages/telegram/_bot.py", line 732, in _do_post
    result = await request.post(
             ^^^^^^^^^^^^^^^^^^^
    ...<6 lines>...
    )
    ^
  File "/root/SWB/venv/lib/python3.13/site-packages/telegram/request/_baserequest.py", line 198, in post
    result = await self._request_wrapper(
             ^^^^^^^^^^^^^^^^^^^^^^^^^^^^
    ...<7 lines>...
    )
    ^
  File "/root/SWB/venv/lib/python3.13/site-packages/telegram/request/_baserequest.py", line 375, in _request_wrapper
    raise exception
telegram.error.Conflict: Conflict: terminated by other getUpdates request; make sure that only one bot instance is running
2025-10-25 22:50:56 - telegram.ext.Updater - ERROR - Exception happened while polling for updates.
Traceback (most recent call last):
  File "/root/SWB/venv/lib/python3.13/site-packages/telegram/ext/_utils/networkloop.py", line 134, in network_retry_loop
    await do_action()
  File "/root/SWB/venv/lib/python3.13/site-packages/telegram/ext/_utils/networkloop.py", line 127, in do_action
    action_cb_task.result()
    ~~~~~~~~~~~~~~~~~~~~~^^
  File "/root/SWB/venv/lib/python3.13/site-packages/telegram/ext/_updater.py", line 340, in polling_action_cb
    updates = await self.bot.get_updates(
              ^^^^^^^^^^^^^^^^^^^^^^^^^^^
    ...<3 lines>...
    )
    ^
  File "/root/SWB/venv/lib/python3.13/site-packages/telegram/ext/_extbot.py", line 676, in get_updates
    updates = await super().get_updates(
              ^^^^^^^^^^^^^^^^^^^^^^^^^^
    ...<9 lines>...
    )
    ^
  File "/root/SWB/venv/lib/python3.13/site-packages/telegram/_bot.py", line 4780, in get_updates
    await self._post(
    ^^^^^^^^^^^^^^^^^
    ...<7 lines>...
    ),
    ^
  File "/root/SWB/venv/lib/python3.13/site-packages/telegram/_bot.py", line 703, in _post
    return await self._do_post(
           ^^^^^^^^^^^^^^^^^^^^
    ...<6 lines>...
    )
    ^
  File "/root/SWB/venv/lib/python3.13/site-packages/telegram/ext/_extbot.py", line 372, in _do_post
    return await super()._do_post(
           ^^^^^^^^^^^^^^^^^^^^^^^
    ...<6 lines>...
    )
    ^
  File "/root/SWB/venv/lib/python3.13/site-packages/telegram/_bot.py", line 732, in _do_post
    result = await request.post(
             ^^^^^^^^^^^^^^^^^^^
    ...<6 lines>...
    )
    ^
  File "/root/SWB/venv/lib/python3.13/site-packages/telegram/request/_baserequest.py", line 198, in post
    result = await self._request_wrapper(
             ^^^^^^^^^^^^^^^^^^^^^^^^^^^^
    ...<7 lines>...
    )
    ^
  File "/root/SWB/venv/lib/python3.13/site-packages/telegram/request/_baserequest.py", line 375, in _request_wrapper
    raise exception
telegram.error.Conflict: Conflict: terminated by other getUpdates request; make sure that only one bot instance is running
2025-10-25 22:50:56 - telegram.ext.Updater - ERROR - Exception happened while polling for updates.
Traceback (most recent call last):
  File "/root/SWB/venv/lib/python3.13/site-packages/telegram/ext/_utils/networkloop.py", line 134, in network_retry_loop
    await do_action()
  File "/root/SWB/venv/lib/python3.13/site-packages/telegram/ext/_utils/networkloop.py", line 127, in do_action
    action_cb_task.result()
    ~~~~~~~~~~~~~~~~~~~~~^^
  File "/root/SWB/venv/lib/python3.13/site-packages/telegram/ext/_updater.py", line 340, in polling_action_cb
    updates = await self.bot.get_updates(
              ^^^^^^^^^^^^^^^^^^^^^^^^^^^
    ...<3 lines>...
    )
    ^
  File "/root/SWB/venv/lib/python3.13/site-packages/telegram/ext/_extbot.py", line 676, in get_updates
    updates = await super().get_updates(
              ^^^^^^^^^^^^^^^^^^^^^^^^^^
    ...<9 lines>...
    )
    ^
  File "/root/SWB/venv/lib/python3.13/site-packages/telegram/_bot.py", line 4780, in get_updates
    await self._post(
    ^^^^^^^^^^^^^^^^^
    ...<7 lines>...
    ),
    ^
  File "/root/SWB/venv/lib/python3.13/site-packages/telegram/_bot.py", line 703, in _post
    return await self._do_post(
           ^^^^^^^^^^^^^^^^^^^^
    ...<6 lines>...
    )
    ^
  File "/root/SWB/venv/lib/python3.13/site-packages/telegram/ext/_extbot.py", line 372, in _do_post
    return await super()._do_post(
           ^^^^^^^^^^^^^^^^^^^^^^^
    ...<6 lines>...
    )
    ^
  File "/root/SWB/venv/lib/python3.13/site-packages/telegram/_bot.py", line 732, in _do_post
    result = await request.post(
             ^^^^^^^^^^^^^^^^^^^
    ...<6 lines>...
    )
    ^
  File "/root/SWB/venv/lib/python3.13/site-packages/telegram/request/_baserequest.py", line 198, in post
    result = await self._request_wrapper(
             ^^^^^^^^^^^^^^^^^^^^^^^^^^^^
    ...<7 lines>...
    )
    ^
  File "/root/SWB/venv/lib/python3.13/site-packages/telegram/request/_baserequest.py", line 375, in _request_wrapper
    raise exception
telegram.error.Conflict: Conflict: terminated by other getUpdates request; make sure that only one bot instance is running
2025-10-2